Workbook
Name Cantidad: COTIZACION!$C$16:$C$46
Name Print_Area: COTIZACION!$B$1:$J$57
Name Descripcion: COTIZACION!$D$16:$H$46
Name TRABAJO: COTIZACION!$D$12
Name Supedido: COTIZACION!$I$11
Name Precioun: COTIZACION!$I$16:$I$46
Name Item: COTIZACION!$B$16:$B$46
Name Provisión_de_perno_SAE_8620__Ø138_mm_x_740_mm_endurecido__según_código_0500060855: COTIZACION!$D$17:$D$46

Sheet COTIZACION
H2: Maestro Vidal 1053 CP 5010 - Córdoba - Argentina | K2: Las celdas marcadas con este color se deben
H3: Tel.: +54 351 4892432 - e-mail: info@kmtl.com.ar | K3: completar manualmente. Las demás tienen fórmulas
B5: FECHA: | F5: COTIZACION Nº: | S5: Horas cotizadas: | T5: =+PRESUPUESTO!F56 -> #REF!
D6: =+PRESUPUESTO!F6 -> #REF! | I6: =PRESUPUESTO!F9 -> #REF!
I7: ="Rev.: "&IF(ISERROR(SEARCH("-",I6,8)),"Oferta inicial",RIGHT(I6,1)) -> Rev.: Oferta inicial
B9: EMPRESA: | D9: =+PRESUPUESTO!F7 -> #REF! | I9: Su pedido de cotización
B10: A PEDIDO DE: | D10: =PRESUPUESTO!F8 -> #REF!
I11: OC 33834
B12: TRABAJO/OBRA: | D12: =PRESUPUESTO!C11 -> #REF!
B14: ITEM | C14: CANTIDAD | D14: DETALLE | I14: PRECIO | J14: PRECIO
I15: UNITARIO | J15: TOTAL
I16: =IF(B16=0,0,LOOKUP(B16,PRESUPUESTO!$B$15:$B$24,PRESUPUESTO!$J$15:$J$24)) -> 0 | J16: =I16*C16 -> 0
I17: =IF(B17=0,0,LOOKUP(B17,PRESUPUESTO!$B$15:$B$24,PRESUPUESTO!$J$15:$J$24)) -> 0 | J17: =I17*C17 -> 0
I18: =IF(B18=0,0,LOOKUP(B18,PRESUPUESTO!$B$15:$B$24,PRESUPUESTO!$J$15:$J$24)) -> 0 | J18: =I18*C18 -> 0
I19: =IF(B19=0,0,LOOKUP(B19,PRESUPUESTO!$B$15:$B$24,PRESUPUESTO!$J$15:$J$24)) -> 0 | J19: =I19*C19 -> 0
I20: =IF(B20=0,0,LOOKUP(B20,PRESUPUESTO!$B$15:$B$24,PRESUPUESTO!$J$15:$J$24)) -> 0 | J20: =I20*C20 -> 0
I21: =IF(B21=0,0,LOOKUP(B21,PRESUPUESTO!$B$15:$B$24,PRESUPUESTO!$J$15:$J$24)) -> 0 | J21: =I21*C21 -> 0
I22: =IF(B22=0,0,LOOKUP(B22,PRESUPUESTO!$B$15:$B$24,PRESUPUESTO!$J$15:$J$24)) -> 0 | J22: =I22*C22 -> 0
I23: =IF(B23=0,0,LOOKUP(B23,PRESUPUESTO!$B$15:$B$24,PRESUPUESTO!$J$15:$J$24)) -> 0 | J23: =I23*C23 -> 0
I24: =IF(B24=0,0,LOOKUP(B24,PRESUPUESTO!$B$15:$B$24,PRESUPUESTO!$J$15:$J$24)) -> 0 | J24: =I24*C24 -> 0
I25: =IF(B25=0,0,LOOKUP(B25,PRESUPUESTO!$B$15:$B$24,PRESUPUESTO!$J$15:$J$24)) -> 0 | J25: =I25*C25 -> 0
I26: =IF(B26=0,0,LOOKUP(B26,PRESUPUESTO!$B$15:$B$24,PRESUPUESTO!$J$15:$J$24)) -> 0 | J26: =I26*C26 -> 0
I27: =IF(B27=0,0,LOOKUP(B27,PRESUPUESTO!$B$15:$B$24,PRESUPUESTO!$J$15:$J$24)) -> 0 | J27: =I27*C27 -> 0
... I31: =IF(B31=0,0,LOOKUP(B31,PRESUPUESTO!$B$15:$B$24,PRESUPUESTO!$J$15:$J$24)) -> 0 | J31: =I31*C31 -> 0
J32: =I32*C32 -> 0
I33: =IF(B33=0,0,LOOKUP(B33,PRESUPUESTO!$B$15:$B$24,PRESUPUESTO!$J$15:$J$24)) -> 0 | J33: =I33*C33 -> 0
I34: =IF(B34=0,0,LOOKUP(B34,PRESUPUESTO!$B$15:$B$24,PRESUPUESTO!$J$15:$J$24)) -> 0 | J34: =I34*C34 -> 0
I35: =IF(B35=0,0,LOOKUP(B35,PRESUPUESTO!$B$15:$B$24,PRESUPUESTO!$J$15:$J$24)) -> 0 | J35: =I35*C35 -> 0
I36: =IF(B36=0,0,LOOKUP(B36,PRESUPUESTO!$B$15:$B$24,PRESUPUESTO!$J$15:$J$24)) -> 0 | J36: =I36*C36 -> 0
I37: =IF(B37=0,0,LOOKUP(B37,PRESUPUESTO!$B$15:$B$24,PRESUPUESTO!$J$15:$J$24)) -> 0 | J37: =I37*C37 -> 0
I38: =IF(B38=0,0,LOOKUP(B38,PRESUPUESTO!$B$15:$B$24,PRESUPUESTO!$J$15:$J$24)) -> 0 | J38: =I38*C38 -> 0
I39: =IF(B39=0,0,LOOKUP(B39,PRESUPUESTO!$B$15:$B$24,PRESUPUESTO!$J$15:$J$24)) -> 0 | J39: =I39*C39 -> 0
I40: =IF(B40=0,0,LOOKUP(B40,PRESUPUESTO!$B$15:$B$24,PRESUPUESTO!$J$15:$J$24)) -> 0 | J40: =I40*C40 -> 0
I41: =IF(B41=0,0,LOOKUP(B41,PRESUPUESTO!$B$15:$B$24,PRESUPUESTO!$J$15:$J$24)) -> 0 | J41: =I41*C41 -> 0
J42: =SUM(J16:J41) -> 0 | K42: << ATENCIÓN: Si esta celda está de color rojo, es porque no coincide la suma con el total del presupuesto
B47: VALOR TOTAL | J47: =J42-J44 -> 0
B50: Precio en: | D50: =+PRESUPUESTO!H6 -> #REF! | I50: Valor de referencia hora UOM hoy | J50: =PRESUPUESTO!H11 -> #REF!
B51: Condición de pago: | D51: =+PRESUPUESTO!H7 -> #REF! | I51: Referencia Dólar billete BNA tipo vendedor hoy | J51: =+PRESUPUESTO!F11 -> #REF!
B52: Lugar de entrega: | D52: =+PRESUPUESTO!H10 -> #REF!
B53: Plazo de entrega: | D53: =+PRESUPUESTO!H8 -> #REF! | E53: días
...
