Workbook
Name TRABAJO_PROYECTO: PRESUPUESTO!$C$11

Sheet PRESUPUESTO
C2: Las celdas marcadas con este color se deben
C3: completar manualmente. Las demás tienen fórmulas | E3: OT N° original: | F3: 02820-26
E6: FECHA: | G6: PRECIO EN:
E7: EMPRESA: | F7: =IF(ISBLANK(F9),"",IFERROR(VLOOKUP($F$9,[1]!Tabla15[#Data],2,0),"OT No encontrada")) -> #ERROR! | G7: FORMA DE PAGO:
E8: SOLICITA: | G8: PLAZO DE ENTREGA: | I8: días
E9: OT N° actual: | G9: VALIDEZ DE OFERTA: | I9: días
E10: ITEMS: | F10: =COUNTA(B15:B24) -> 0 | G10: LUGAR DE ENTREGA:
B11: TRABAJO/ PROYECTO: | C11: =IF(ISBLANK(F9),"",IFERROR(VLOOKUP($F$9,[1]!Tabla15[#Data],3,0),"OT No encontrada en el archivo de seguimiento. Verifique por favor !!")) -> #ERROR! | E11: DÓLAR REFERENCIA | H11: 6418.6
B13: RESUMEN DEL TRABAJO
B14: ITEM | C14: DESCRIPCION | D14: CANTIDAD | E14: COSTO MATERIALES | F14: COSTO MANO DE OBRA INTERNA | G14: COSTO SERVICIOS TERCEROS | H14: COSTO TOTAL MA+MO+ST | I14: COSTO UNITARIO | J14: PRECIO VENTA UNITARIO | K14: PRECIO VENTA TOTAL | L14: UTILIDAD NETA [$]
E15: =IFERROR(IF($H$6="USD + IVA",(SUMIFS($G$31:$G$40,$B$31:$B$40,B15,$K$31:$K$40,"No")/$F$11*D15)+(SUMIFS($G$31:$G$40,$B$31:$B$40,B15,$K$31:$K$40,"Si")/$F$11),(SUMIFS($G$31:$G$40,$B$31:$B$40,B15,$K$31:$K$40,"No")*D15)+(SUMIFS($G$31:$G$40,$B$31:$B$40,B15,$K$31:$K$40,"Si"))),0) -> 0 | F15: =IFERROR(IF($H$6="USD + IVA",(SUMIFS($F$46:$F$55,$B$46:$B$55,B15,$I$46:$I$55,"No")/$F$11*D15)+(SUMIFS($F$46:$F$55,$B$46:$B$55,B15,$I$46:$I$55,"Si")/$F$11),(SUMIFS($F$46:$F$55,$B$46:$B$55,B15,$I$46:$I$55,"No")*D15)+(SUMIFS($F$46:$F$55,$B$46:$B$55,B15,$I$46:$I$55,"Si"))),0) -> 0 | G15: =IFERROR(IF($H$6="USD + IVA",(SUMIFS($G$61:$G$70,$B$61:$B$70,B15,$K$61:$K$70,"No")/$F$11*D15)+(SUMIFS($G$61:$G$70,$B$61:$B$70,B15,$K$61:$K$70,"Si")/$F$11),(SUMIFS($G$61:$G$70,$B$61:$B$70,B15,$K$61:$K$70,"No")*D15)+(SUMIFS($G$61:$G$70,$B$61:$B$70,B15,$K$61:$K$70,"Si"))),0) -> 0 | H15: =SUM(E15:G15) -> 0 | I15: =IF(D15>0,H15/D15,0) -> 0 | J15: =IFERROR(IF($H$6="USD + IVA",(SUMIFS($J$31:$J$40,$B$31:$B$40,B15,$K$31:$K$40,"No")/$F$11)+(SUMIFS($J$31:$J$40,$B$31:$B$40,B15,$K$31:$K$40,"Si")/$F$11)/D15,(SUMIFS($J$31:$J$40,$B$31:$B$40,B15,$K$31:$K$40,"No"))+(SUMIFS($J$31:$J$40,$B$31:$B$40,B15,$K$31:$K$40,"Si"))/D15),0)+IFERROR(IF($H$6="USD + IVA",(SUMIFS($H$46:$H$55,$B$46:$B$55,B15,$I$46:$I$55,"No")/$F$11)+(SUMIFS($H$46:$H$55,$B$46:$B$55,B15,$I$46:$I$55,"Si")/$F$11)/D15,(SUMIFS($H$46:$H$55,$B$46:$B$55,B15,$I$46:$I$55,"No"))+(SUMIFS($H$46:$H$55,$B$46:$B$55,B15,$I$46:$I$55,"Si"))/D15),0)+IFERROR(IF($H$6="USD + IVA",(SUMIFS($J$61:$J$70,$B$61:$B$70,B15,$K$61:$K$70,"No")/$F$11)+(SUMIFS($J$61:$J$70,$B$61:$B$70,B15,$K$61:$K$70,"Si")/$F$11)/D15,(SUMIFS($J$61:$J$70,$B$61:$B$70,B15,$K$61:$K$70,"No"))+(SUMIFS($J$61:$J$70,$B$61:$B$70,B15,$K$61:$K$70,"Si"))/D15),0) -> 0 | K15: =J15*D15 -> 0 | L15: =K15-H15 -> 0
E16: =IFERROR(IF($H$6="USD + IVA",(SUMIFS($G$31:$G$40,$B$31:$B$40,B16,$K$31:$K$40,"No")/$F$11*D16)+(SUMIFS($G$31:$G$40,$B$31:$B$40,B16,$K$31:$K$40,"Si")/$F$11),(SUMIFS($G$31:$G$40,$B$31:$B$40,B16,$K$31:$K$40,"No")*D16)+(SUMIFS($G$31:$G$40,$B$31:$B$40,B16,$K$31:$K$40,"Si"))),0) -> 0 | F16: =IFERROR(IF($H$6="USD + IVA",(SUMIFS($F$46:$F$55,$B$46:$B$55,B16,$I$46:$I$55,"No")/$F$11*D16)+(SUMIFS($F$46:$F$55,$B$46:$B$55,B16,$I$46:$I$55,"Si")/$F$11),(SUMIFS($F$46:$F$55,$B$46:$B$55,B16,$I$46:$I$55,"No")*D16)+(SUMIFS($F$46:$F$55,$B$46:$B$55,B16,$I$46:$I$55,"Si"))),0) -> 0 | G16: =IFERROR(IF($H$6="USD + IVA",(SUMIFS($G$61:$G$70,$B$61:$B$70,B16,$K$61:$K$70,"No")/$F$11*D16)+(SUMIFS($G$61:$G$70,$B$61:$B$70,B16,$K$61:$K$70,"Si")/$F$11),(SUMIFS($G$61:$G$70,$B$61:$B$70,B16,$K$61:$K$70,"No")*D16)+(SUMIFS($G$61:$G$70,$B$61:$B$70,B16,$K$61:$K$70,"Si"))),0) -> 0 | H16: =SUM(E16:G16) -> 0 | I16: =IF(D16>0,H16/D16,0) -> 0 | J16: =IFERROR(IF($H$6="USD + IVA",(SUMIFS($J$31:$J$40,$B$31:$B$40,B16,$K$31:$K$40,"No")/$F$11)+(SUMIFS($J$31:$J$40,$B$31:$B$40,B16,$K$31:$K$40,"Si")/$F$11)/D16,(SUMIFS($J$31:$J$40,$B$31:$B$40,B16,$K$31:$K$40,"No"))+(SUMIFS($J$31:$J$40,$B$31:$B$40,B16,$K$31:$K$40,"Si"))/D16),0)+IFERROR(IF($H$6="USD + IVA",(SUMIFS($H$46:$H$55,$B$46:$B$55,B16,$I$46:$I$55,"No")/$F$11)+(SUMIFS($H$46:$H$55,$B$46:$B$55,B16,$I$46:$I$55,"Si")/$F$11)/D16,(SUMIFS($H$46:$H$55,$B$46:$B$55,B16,$I$46:$I$55,"No"))+(SUMIFS($H$46:$H$55,$B$46:$B$55,B16,$I$46:$I$55,"Si"))/D16),0)+IFERROR(IF($H$6="USD + IVA",(SUMIFS($J$61:$J$70,$B$61:$B$70,B16,$K$61:$K$70,"No")/$F$11)+(SUMIFS($J$61:$J$70,$B$61:$B$70,B16,$K$61:$K$70,"Si")/$F$11)/D16,(SUMIFS($J$61:$J$70,$B$61:$B$70,B16,$K$61:$K$70,"No"))+(SUMIFS($J$61:$J$70,$B$61:$B$70,B16,$K$61:$K$70,"Si"))/D16),0) -> 0 | K16: =J16*D16 -> 0 | L16: =K16-H16 -> 0
E17: =IFERROR(IF($H$6="USD + IVA",(SUMIFS($G$31:$G$40,$B$31:$B$40,B17,$K$31:$K$40,"No")/$F$11*D17)+(SUMIFS($G$31:$G$40,$B$31:$B$40,B17,$K$31:$K$40,"Si")/$F$11),(SUMIFS($G$31:$G$40,$B$31:$B$40,B17,$K$31:$K$40,"No")*D17)+(SUMIFS($G$31:$G$40,$B$31:$B$40,B17,$K$31:$K$40,"Si"))),0) -> 0 | F17: =IFERROR(IF($H$6="USD + IVA",(SUMIFS($F$46:$F$55,$B$46:$B$55,B17,$I$46:$I$55,"No")/$F$11*D17)+(SUMIFS($F$46:$F$55,$B$46:$B$55,B17,$I$46:$I$55,"Si")/$F$11),(SUMIFS($F$46:$F$55,$B$46:$B$55,B17,$I$46:$I$55,"No")*D17)+(SUMIFS($F$46:$F$55,$B$46:$B$55,B17,$I$46:$I$55,"Si"))),0) -> 0 | G17: =IFERROR(IF($H$6="USD + IVA",(SUMIFS($G$61:$G$70,$B$61:$B$70,B17,$K$61:$K$70,"No")/$F$11*D17)+(SUMIFS($G$61:$G$70,$B$61:$B$70,B17,$K$61:$K$70,"Si")/$F$11),(SUMIFS($G$61:$G$70,$B$61:$B$70,B17,$K$61:$K$70,"No")*D17)+(SUMIFS($G$61:$G$70,$B$61:$B$70,B17,$K$61:$K$70,"Si"))),0) -> 0 | H17: =SUM(E17:G17) -> 0 | I17: =IF(D17>0,H17/D17,0) -> 0 | J17: =IFERROR(IF($H$6="USD + IVA",(SUMIFS($J$31:$J$40,$B$31:$B$40,B17,$K$31:$K$40,"No")/$F$11)+(SUMIFS($J$31:$J$40,$B$31:$B$40,B17,$K$31:$K$40,"Si")/$F$11)/D17,(SUMIFS($J$31:$J$40,$B$31:$B$40,B17,$K$31:$K$40,"No"))+(SUMIFS($J$31:$J$40,$B$31:$B$40,B17,$K$31:$K$40,"Si"))/D17),0)+IFERROR(IF($H$6="USD + IVA",(SUMIFS($H$46:$H$55,$B$46:$B$55,B17,$I$46:$I$55,"No")/$F$11)+(SUMIFS($H$46:$H$55,$B$46:$B$55,B17,$I$46:$I$55,"Si")/$F$11)/D17,(SUMIFS($H$46:$H$55,$B$46:$B$55,B17,$I$46:$I$55,"No"))+(SUMIFS($H$46:$H$55,$B$46:$B$55,B17,$I$46:$I$55,"Si"))/D17),0)+IFERROR(IF($H$6="USD + IVA",(SUMIFS($J$61:$J$70,$B$61:$B$70,B17,$K$61:$K$70,"No")/$F$11)+(SUMIFS($J$61:$J$70,$B$61:$B$70,B17,$K$61:$K$70,"Si")/$F$11)/D17,(SUMIFS($J$61:$J$70,$B$61:$B$70,B17,$K$61:$K$70,"No"))+(SUMIFS($J$61:$J$70,$B$61:$B$70,B17,$K$61:$K$70,"Si"))/D17),0) -> 0 | K17: =J17*D17 -> 0 | L17: =K17-H17 -> 0
E18: =IFERROR(IF($H$6="USD + IVA",(SUMIFS($G$31:$G$40,$B$31:$B$40,B18,$K$31:$K$40,"No")/$F$11*D18)+(SUMIFS($G$31:$G$40,$B$31:$B$40,B18,$K$31:$K$40,"Si")/$F$11),(SUMIFS($G$31:$G$40,$B$31:$B$40,B18,$K$31:$K$40,"No")*D18)+(SUMIFS($G$31:$G$40,$B$31:$B$40,B18,$K$31:$K$40,"Si"))),0) -> 0 | F18: =IFERROR(IF($H$6="USD + IVA",(SUMIFS($F$46:$F$55,$B$46:$B$55,B18,$I$46:$I$55,"No")/$F$11*D18)+(SUMIFS($F$46:$F$55,$B$46:$B$55,B18,$I$46:$I$55,"Si")/$F$11),(SUMIFS($F$46:$F$55,$B$46:$B$55,B18,$I$46:$I$55,"No")*D18)+(SUMIFS($F$46:$F$55,$B$46:$B$55,B18,$I$46:$I$55,"Si"))),0) -> 0 | G18: =IFERROR(IF($H$6="USD + IVA",(SUMIFS($G$61:$G$70,$B$61:$B$70,B18,$K$61:$K$70,"No")/$F$11*D18)+(SUMIFS($G$61:$G$70,$B$61:$B$70,B18,$K$61:$K$70,"Si")/$F$11),(SUMIFS($G$61:$G$70,$B$61:$B$70,B18,$K$61:$K$70,"No")*D18)+(SUMIFS($G$61:$G$70,$B$61:$B$70,B18,$K$61:$K$70,"Si"))),0) -> 0 | H18: =SUM(E18:G18) -> 0 | I18: =IF(D18>0,H18/D18,0) -> 0 | J18: =IFERROR(IF($H$6="USD + IVA",(SUMIFS($J$31:$J$40,$B$31:$B$40,B18,$K$31:$K$40,"No")/$F$11)+(SUMIFS($J$31:$J$40,$B$31:$B$40,B18,$K$31:$K$40,"Si")/$F$11)/D18,(SUMIFS($J$31:$J$40,$B$31:$B$40,B18,$K$31:$K$40,"No"))+(SUMIFS($J$31:$J$40,$B$31:$B$40,B18,$K$31:$K$40,"Si"))/D18),0)+IFERROR(IF($H$6="USD + IVA",(SUMIFS($H$46:$H$55,$B$46:$B$55,B18,$I$46:$I$55,"No")/$F$11)+(SUMIFS($H$46:$H$55,$B$46:$B$55,B18,$I$46:$I$55,"Si")/$F$11)/D18,(SUMIFS($H$46:$H$55,$B$46:$B$55,B18,$I$46:$I$55,"No"))+(SUMIFS($H$46:$H$55,$B$46:$B$55,B18,$I$46:$I$55,"Si"))/D18),0)+IFERROR(IF($H$6="USD + IVA",(SUMIFS($J$61:$J$70,$B$61:$B$70,B18,$K$61:$K$70,"No")/$F$11)+(SUMIFS($J$61:$J$70,$B$61:$B$70,B18,$K$61:$K$70,"Si")/$F$11)/D18,(SUMIFS($J$61:$J$70,$B$61:$B$70,B18,$K$61:$K$70,"No"))+(SUMIFS($J$61:$J$70,$B$61:$B$70,B18,$K$61:$K$70,"Si"))/D18),0) -> 0 | K18: =J18*D18 -> 0 | L18: =K18-H18 -> 0
E19: =IFERROR(IF($H$6="USD + IVA",(SUMIFS($G$31:$G$40,$B$31:$B$40,B19,$K$31:$K$40,"No")/$F$11*D19)+(SUMIFS($G$31:$G$40,$B$31:$B$40,B19,$K$31:$K$40,"Si")/$F$11),(SUMIFS($G$31:$G$40,$B$31:$B$40,B19,$K$31:$K$40,"No")*D19)+(SUMIFS($G$31:$G$40,$B$31:$B$40,B19,$K$31:$K$40,"Si"))),0) -> 0 | F19: =IFERROR(IF($H$6="USD + IVA",(SUMIFS($F$46:$F$55,$B$46:$B$55,B19,$I$46:$I$55,"No")/$F$11*D19)+(SUMIFS($F$46:$F$55,$B$46:$B$55,B19,$I$46:$I$55,"Si")/$F$11),(SUMIFS($F$46:$F$55,$B$46:$B$55,B19,$I$46:$I$55,"No")*D19)+(SUMIFS($F$46:$F$55,$B$46:$B$55,B19,$I$46:$I$55,"Si"))),0) -> 0 | G19: =IFERROR(IF($H$6="USD + IVA",(SUMIFS($G$61:$G$70,$B$61:$B$70,B19,$K$61:$K$70,"No")/$F$11*D19)+(SUMIFS($G$61:$G$70,$B$61:$B$70,B19,$K$61:$K$70,"Si")/$F$11),(SUMIFS($G$61:$G$70,$B$61:$B$70,B19,$K$61:$K$70,"No")*D19)+(SUMIFS($G$61:$G$70,$B$61:$B$70,B19,$K$61:$K$70,"Si"))),0) -> 0 | H19: =SUM(E19:G19) -> 0 | I19: =IF(D19>0,H19/D19,0) -> 0 | J19: =IFERROR(IF($H$6="USD + IVA",(SUMIFS($J$31:$J$40,$B$31:$B$40,B19,$K$31:$K$40,"No")/$F$11)+(SUMIFS($J$31:$J$40,$B$31:$B$40,B19,$K$31:$K$40,"Si")/$F$11)/D19,(SUMIFS($J$31:$J$40,$B$31:$B$40,B19,$K$31:$K$40,"No"))+(SUMIFS($J$31:$J$40,$B$31:$B$40,B19,$K$31:$K$40,"Si"))/D19),0)+IFERROR(IF($H$6="USD + IVA",(SUMIFS($H$46:$H$55,$B$46:$B$55,B19,$I$46:$I$55,"No")/$F$11)+(SUMIFS($H$46:$H$55,$B$46:$B$55,B19,$I$46:$I$55,"Si")/$F$11)/D19,(SUMIFS($H$46:$H$55,$B$46:$B$55,B19,$I$46:$I$55,"No"))+(SUMIFS($H$46:$H$55,$B$46:$B$55,B19,$I$46:$I$55,"Si"))/D19),0)+IFERROR(IF($H$6="USD + IVA",(SUMIFS($J$61:$J$70,$B$61:$B$70,B19,$K$61:$K$70,"No")/$F$11)+(SUMIFS($J$61:$J$70,$B$61:$B$70,B19,$K$61:$K$70,"Si")/$F$11)/D19,(SUMIFS($J$61:$J$70,$B$61:$B$70,B19,$K$61:$K$70,"No"))+(SUMIFS($J$61:$J$70,$B$61:$B$70,B19,$K$61:$K$70,"Si"))/D19),0) -> 0 | K19: =J19*D19 -> 0 | L19: =K19-H19 -> 0
E20: =IFERROR(IF($H$6="USD + IVA",(SUMIFS($G$31:$G$40,$B$31:$B$40,B20,$K$31:$K$40,"No")/$F$11*D20)+(SUMIFS($G$31:$G$40,$B$31:$B$40,B20,$K$31:$K$40,"Si")/$F$11),(SUMIFS($G$31:$G$40,$B$31:$B$40,B20,$K$31:$K$40,"No")*D20)+(SUMIFS($G$31:$G$40,$B$31:$B$40,B20,$K$31:$K$40,"Si"))),0) -> 0 | F20: =IFERROR(IF($H$6="USD + IVA",(SUMIFS($F$46:$F$55,$B$46:$B$55,B20,$I$46:$I$55,"No")/$F$11*D20)+(SUMIFS($F$46:$F$55,$B$46:$B$55,B20,$I$46:$I$55,"Si")/$F$11),(SUMIFS($F$46:$F$55,$B$46:$B$55,B20,$I$46:$I$55,"No")*D20)+(SUMIFS($F$46:$F$55,$B$46:$B$55,B20,$I$46:$I$55,"Si"))),0) -> 0 | G20: =IFERROR(IF($H$6="USD + IVA",(SUMIFS($G$61:$G$70,$B$61:$B$70,B20,$K$61:$K$70,"No")/$F$11*D20)+(SUMIFS($G$61:$G$70,$B$61:$B$70,B20,$K$61:$K$70,"Si")/$F$11),(SUMIFS($G$61:$G$70,$B$61:$B$70,B20,$K$61:$K$70,"No")*D20)+(SUMIFS($G$61:$G$70,$B$61:$B$70,B20,$K$61:$K$70,"Si"))),0) -> 0 | H20: =SUM(E20:G20) -> 0 | I20: =IF(D20>0,H20/D20,0) -> 0 | J20: =IFERROR(IF($H$6="USD + IVA",(SUMIFS($J$31:$J$40,$B$31:$B$40,B20,$K$31:$K$40,"No")/$F$11)+(SUMIFS($J$31:$J$40,$B$31:$B$40,B20,$K$31:$K$40,"Si")/$F$11)/D20,(SUMIFS($J$31:$J$40,$B$31:$B$40,B20,$K$31:$K$40,"No"))+(SUMIFS($J$31:$J$40,$B$31:$B$40,B20,$K$31:$K$40,"Si"))/D20),0)+IFERROR(IF($H$6="USD + IVA",(SUMIFS($H$46:$H$55,$B$46:$B$55,B20,$I$46:$I$55,"No")/$F$11)+(SUMIFS($H$46:$H$55,$B$46:$B$55,B20,$I$46:$I$55,"Si")/$F$11)/D20,(SUMIFS($H$46:$H$55,$B$46:$B$55,B20,$I$46:$I$55,"No"))+(SUMIFS($H$46:$H$55,$B$46:$B$55,B20,$I$46:$I$55,"Si"))/D20),0)+IFERROR(IF($H$6="USD + IVA",(SUMIFS($J$61:$J$70,$B$61:$B$70,B20,$K$61:$K$70,"No")/$F$11)+(SUMIFS($J$61:$J$70,$B$61:$B$70,B20,$K$61:$K$70,"Si")/$F$11)/D20,(SUMIFS($J$61:$J$70,$B$61:$B$70,B20,$K$61:$K$70,"No"))+(SUMIFS($J$61:$J$70,$B$61:$B$70,B20,$K$61:$K$70,"Si"))/D20),0) -> 0 | K20: =J20*D20 -> 0 | L20: =K20-H20 -> 0
E21: =IFERROR(IF($H$6="USD + IVA",(SUMIFS($G$31:$G$40,$B$31:$B$40,B21,$K$31:$K$40,"No")/$F$11*D21)+(SUMIFS($G$31:$G$40,$B$31:$B$40,B21,$K$31:$K$40,"Si")/$F$11),(SUMIFS($G$31:$G$40,$B$31:$B$40,B21,$K$31:$K$40,"No")*D21)+(SUMIFS($G$31:$G$40,$B$31:$B$40,B21,$K$31:$K$40,"Si"))),0) -> 0 | F21: =IFERROR(IF($H$6="USD + IVA",(SUMIFS($F$46:$F$55,$B$46:$B$55,B21,$I$46:$I$55,"No")/$F$11*D21)+(SUMIFS($F$46:$F$55,$B$46:$B$55,B21,$I$46:$I$55,"Si")/$F$11),(SUMIFS($F$46:$F$55,$B$46:$B$55,B21,$I$46:$I$55,"No")*D21)+(SUMIFS($F$46:$F$55,$B$46:$B$55,B21,$I$46:$I$55,"Si"))),0) -> 0 | G21: =IFERROR(IF($H$6="USD + IVA",(SUMIFS($G$61:$G$70,$B$61:$B$70,B21,$K$61:$K$70,"No")/$F$11*D21)+(SUMIFS($G$61:$G$70,$B$61:$B$70,B21,$K$61:$K$70,"Si")/$F$11),(SUMIFS($G$61:$G$70,$B$61:$B$70,B21,$K$61:$K$70,"No")*D21)+(SUMIFS($G$61:$G$70,$B$61:$B$70,B21,$K$61:$K$70,"Si"))),0) -> 0 | H21: =SUM(E21:G21) -> 0 | I21: =IF(D21>0,H21/D21,0) -> 0 | J21: =IFERROR(IF($H$6="USD + IVA",(SUMIFS($J$31:$J$40,$B$31:$B$40,B21,$K$31:$K$40,"No")/$F$11)+(SUMIFS($J$31:$J$40,$B$31:$B$40,B21,$K$31:$K$40,"Si")/$F$11)/D21,(SUMIFS($J$31:$J$40,$B$31:$B$40,B21,$K$31:$K$40,"No"))+(SUMIFS($J$31:$J$40,$B$31:$B$40,B21,$K$31:$K$40,"Si"))/D21),0)+IFERROR(IF($H$6="USD + IVA",(SUMIFS($H$46:$H$55,$B$46:$B$55,B21,$I$46:$I$55,"No")/$F$11)+(SUMIFS($H$46:$H$55,$B$46:$B$55,B21,$I$46:$I$55,"Si")/$F$11)/D21,(SUMIFS($H$46:$H$55,$B$46:$B$55,B21,$I$46:$I$55,"No"))+(SUMIFS($H$46:$H$55,$B$46:$B$55,B21,$I$46:$I$55,"Si"))/D21),0)+IFERROR(IF($H$6="USD + IVA",(SUMIFS($J$61:$J$70,$B$61:$B$70,B21,$K$61:$K$70,"No")/$F$11)+(SUMIFS($J$61:$J$70,$B$61:$B$70,B21,$K$61:$K$70,"Si")/$F$11)/D21,(SUMIFS($J$61:$J$70,$B$61:$B$70,B21,$K$61:$K$70,"No"))+(SUMIFS($J$61:$J$70,$B$61:$B$70,B21,$K$61:$K$70,"Si"))/D21),0) -> 0 | K21: =J21*D21 -> 0 | L21: =K21-H21 -> 0
E22: =IFERROR(IF($H$6="USD + IVA",(SUMIFS($G$31:$G$40,$B$31:$B$40,B22,$K$31:$K$40,"No")/$F$11*D22)+(SUMIFS($G$31:$G$40,$B$31:$B$40,B22,$K$31:$K$40,"Si")/$F$11),(SUMIFS($G$31:$G$40,$B$31:$B$40,B22,$K$31:$K$40,"No")*D22)+(SUMIFS($G$31:$G$40,$B$31:$B$40,B22,$K$31:$K$40,"Si"))),0) -> 0 | F22: =IFERROR(IF($H$6="USD + IVA",(SUMIFS($F$46:$F$55,$B$46:$B$55,B22,$I$46:$I$55,"No")/$F$11*D22)+(SUMIFS($F$46:$F$55,$B$46:$B$55,B22,$I$46:$I$55,"Si")/$F$11),(SUMIFS($F$46:$F$55,$B$46:$B$55,B22,$I$46:$I$55,"No")*D22)+(SUMIFS($F$46:$F$55,$B$46:$B$55,B22,$I$46:$I$55,"Si"))),0) -> 0 | G22: =IFERROR(IF($H$6="USD + IVA",(SUMIFS($G$61:$G$70,$B$61:$B$70,B22,$K$61:$K$70,"No")/$F$11*D22)+(SUMIFS($G$61:$G$70,$B$61:$B$70,B22,$K$61:$K$70,"Si")/$F$11),(SUMIFS($G$61:$G$70,$B$61:$B$70,B22,$K$61:$K$70,"No")*D22)+(SUMIFS($G$61:$G$70,$B$61:$B$70,B22,$K$61:$K$70,"Si"))),0) -> 0 | H22: =SUM(E22:G22) -> 0 | I22: =IF(D22>0,H22/D22,0) -> 0 | J22: =IFERROR(IF($H$6="USD + IVA",(SUMIFS($J$31:$J$40,$B$31:$B$40,B22,$K$31:$K$40,"No")/$F$11)+(SUMIFS($J$31:$J$40,$B$31:$B$40,B22,$K$31:$K$40,"Si")/$F$11)/D22,(SUMIFS($J$31:$J$40,$B$31:$B$40,B22,$K$31:$K$40,"No"))+(SUMIFS($J$31:$J$40,$B$31:$B$40,B22,$K$31:$K$40,"Si"))/D22),0)+IFERROR(IF($H$6="USD + IVA",(SUMIFS($H$46:$H$55,$B$46:$B$55,B22,$I$46:$I$55,"No")/$F$11)+(SUMIFS($H$46:$H$55,$B$46:$B$55,B22,$I$46:$I$55,"Si")/$F$11)/D22,(SUMIFS($H$46:$H$55,$B$46:$B$55,B22,$I$46:$I$55,"No"))+(SUMIFS($H$46:$H$55,$B$46:$B$55,B22,$I$46:$I$55,"Si"))/D22),0)+IFERROR(IF($H$6="USD + IVA",(SUMIFS($J$61:$J$70,$B$61:$B$70,B22,$K$61:$K$70,"No")/$F$11)+(SUMIFS($J$61:$J$70,$B$61:$B$70,B22,$K$61:$K$70,"Si")/$F$11)/D22,(SUMIFS($J$61:$J$70,$B$61:$B$70,B22,$K$61:$K$70,"No"))+(SUMIFS($J$61:$J$70,$B$61:$B$70,B22,$K$61:$K$70,"Si"))/D22),0) -> 0 | K22: =J22*D22 -> 0 | L22: =K22-H22 -> 0
E23: =IFERROR(IF($H$6="USD + IVA",(SUMIFS($G$31:$G$40,$B$31:$B$40,B23,$K$31:$K$40,"No")/$F$11*D23)+(SUMIFS($G$31:$G$40,$B$31:$B$40,B23,$K$31:$K$40,"Si")/$F$11),(SUMIFS($G$31:$G$40,$B$31:$B$40,B23,$K$31:$K$40,"No")*D23)+(SUMIFS($G$31:$G$40,$B$31:$B$40,B23,$K$31:$K$40,"Si"))),0) -> 0 | F23: =IFERROR(IF($H$6="USD + IVA",(SUMIFS($F$46:$F$55,$B$46:$B$55,B23,$I$46:$I$55,"No")/$F$11*D23)+(SUMIFS($F$46:$F$55,$B$46:$B$55,B23,$I$46:$I$55,"Si")/$F$11),(SUMIFS($F$46:$F$55,$B$46:$B$55,B23,$I$46:$I$55,"No")*D23)+(SUMIFS($F$46:$F$55,$B$46:$B$55,B23,$I$46:$I$55,"Si"))),0) -> 0 | G23: =IFERROR(IF($H$6="USD + IVA",(SUMIFS($G$61:$G$70,$B$61:$B$70,B23,$K$61:$K$70,"No")/$F$11*D23)+(SUMIFS($G$61:$G$70,$B$61:$B$70,B23,$K$61:$K$70,"Si")/$F$11),(SUMIFS($G$61:$G$70,$B$61:$B$70,B23,$K$61:$K$70,"No")*D23)+(SUMIFS($G$61:$G$70,$B$61:$B$70,B23,$K$61:$K$70,"Si"))),0) -> 0 | H23: =SUM(E23:G23) -> 0 | I23: =IF(D23>0,H23/D23,0) -> 0 | J23: =IFERROR(IF($H$6="USD + IVA",(SUMIFS($J$31:$J$40,$B$31:$B$40,B23,$K$31:$K$40,"No")/$F$11)+(SUMIFS($J$31:$J$40,$B$31:$B$40,B23,$K$31:$K$40,"Si")/$F$11)/D23,(SUMIFS($J$31:$J$40,$B$31:$B$40,B23,$K$31:$K$40,"No"))+(SUMIFS($J$31:$J$40,$B$31:$B$40,B23,$K$31:$K$40,"Si"))/D23),0)+IFERROR(IF($H$6="USD + IVA",(SUMIFS($H$46:$H$55,$B$46:$B$55,B23,$I$46:$I$55,"No")/$F$11)+(SUMIFS($H$46:$H$55,$B$46:$B$55,B23,$I$46:$I$55,"Si")/$F$11)/D23,(SUMIFS($H$46:$H$55,$B$46:$B$55,B23,$I$46:$I$55,"No"))+(SUMIFS($H$46:$H$55,$B$46:$B$55,B23,$I$46:$I$55,"Si"))/D23),0)+IFERROR(IF($H$6="USD + IVA",(SUMIFS($J$61:$J$70,$B$61:$B$70,B23,$K$61:$K$70,"No")/$F$11)+(SUMIFS($J$61:$J$70,$B$61:$B$70,B23,$K$61:$K$70,"Si")/$F$11)/D23,(SUMIFS($J$61:$J$70,$B$61:$B$70,B23,$K$61:$K$70,"No"))+(SUMIFS($J$61:$J$70,$B$61:$B$70,B23,$K$61:$K$70,"Si"))/D23),0) -> 0 | K23: =J23*D23 -> 0 | L23: =K23-H23 -> 0
E24: =IFERROR(IF($H$6="USD + IVA",(SUMIFS($G$31:$G$40,$B$31:$B$40,B24,$K$31:$K$40,"No")/$F$11*D24)+(SUMIFS($G$31:$G$40,$B$31:$B$40,B24,$K$31:$K$40,"Si")/$F$11),(SUMIFS($G$31:$G$40,$B$31:$B$40,B24,$K$31:$K$40,"No")*D24)+(SUMIFS($G$31:$G$40,$B$31:$B$40,B24,$K$31:$K$40,"Si"))),0) -> 0 | F24: =IFERROR(IF($H$6="USD + IVA",(SUMIFS($F$46:$F$55,$B$46:$B$55,B24,$I$46:$I$55,"No")/$F$11*D24)+(SUMIFS($F$46:$F$55,$B$46:$B$55,B24,$I$46:$I$55,"Si")/$F$11),(SUMIFS($F$46:$F$55,$B$46:$B$55,B24,$I$46:$I$55,"No")*D24)+(SUMIFS($F$46:$F$55,$B$46:$B$55,B24,$I$46:$I$55,"Si"))),0) -> 0 | G24: =IFERROR(IF($H$6="USD + IVA",(SUMIFS($G$61:$G$70,$B$61:$B$70,B24,$K$61:$K$70,"No")/$F$11*D24)+(SUMIFS($G$61:$G$70,$B$61:$B$70,B24,$K$61:$K$70,"Si")/$F$11),(SUMIFS($G$61:$G$70,$B$61:$B$70,B24,$K$61:$K$70,"No")*D24)+(SUMIFS($G$61:$G$70,$B$61:$B$70,B24,$K$61:$K$70,"Si"))),0) -> 0 | H24: =SUM(E24:G24) -> 0 | I24: =IF(D24>0,H24/D24,0) -> 0 | J24: =IFERROR(IF($H$6="USD + IVA",(SUMIFS($J$31:$J$40,$B$31:$B$40,B24,$K$31:$K$40,"No")/$F$11)+(SUMIFS($J$31:$J$40,$B$31:$B$40,B24,$K$31:$K$40,"Si")/$F$11)/D24,(SUMIFS($J$31:$J$40,$B$31:$B$40,B24,$K$31:$K$40,"No"))+(SUMIFS($J$31:$J$40,$B$31:$B$40,B24,$K$31:$K$40,"Si"))/D24),0)+IFERROR(IF($H$6="USD + IVA",(SUMIFS($H$46:$H$55,$B$46:$B$55,B24,$I$46:$I$55,"No")/$F$11)+(SUMIFS($H$46:$H$55,$B$46:$B$55,B24,$I$46:$I$55,"Si")/$F$11)/D24,(SUMIFS($H$46:$H$55,$B$46:$B$55,B24,$I$46:$I$55,"No"))+(SUMIFS($H$46:$H$55,$B$46:$B$55,B24,$I$46:$I$55,"Si"))/D24),0)+IFERROR(IF($H$6="USD + IVA",(SUMIFS($J$61:$J$70,$B$61:$B$70,B24,$K$61:$K$70,"No")/$F$11)+(SUMIFS($J$61:$J$70,$B$61:$B$70,B24,$K$61:$K$70,"Si")/$F$11)/D24,(SUMIFS($J$61:$J$70,$B$61:$B$70,B24,$K$61:$K$70,"No"))+(SUMIFS($J$61:$J$70,$B$61:$B$70,B24,$K$61:$K$70,"Si"))/D24),0) -> 0 | K24: =J24*D24 -> 0 | L24: =K24-H24 -> 0
J26: TOTALES | K26: =SUM(K15:K24) -> 0 | L26: =SUM(L15:L24) -> 0
K27: % DESCUENTO | L27: MONTO DESCUENTO [$] | M27: Ajuste en % | N27: % UTILIDAD GLOBAL | O27: $ UTILIDAD GLOBAL
K28: 0 | L28: =K26*K28 -> 0 | M28: 0 | N28: =AVERAGE(I41,G56,I71)*(1+$M$28) -> 0 | O28: =L26 -> 0
B29: MATERIALES
B30: ITEM | C30: DESCRIPCION | D30: CANTIDAD | E30: COSTO UNITARIO | F30: Moneda | G30: Costo Total en [$] | H30: PROVEEDOR | I30: % de utilidad | J30: Venta en [$] | K30: ES GLOBAL
G31: =IF(F31="USD",D31*E31*$F$11,IF(F31="Pesos",D31*E31,"<< Moneda ?")) -> << Moneda ? | J31: =IFERROR(G31*(1+I31)*(1+$M$28),0) -> 0 | K31: No
G32: =IF(F32="USD",D32*E32*$F$11,IF(F32="Pesos",D32*E32,"<< Moneda ?")) -> << Moneda ? | J32: =IFERROR(G32*(1+I32)*(1+$M$28),0) -> 0 | K32: No
G33: =IF(F33="USD",D33*E33*$F$11,IF(F33="Pesos",D33*E33,"<< Moneda ?")) -> << Moneda ? | J33: =IFERROR(G33*(1+I33)*(1+$M$28),0) -> 0 | K33: No
G34: =IF(F34="USD",D34*E34*$F$11,IF(F34="Pesos",D34*E34,"<< Moneda ?")) -> << Moneda ? | J34: =IFERROR(G34*(1+I34)*(1+$M$28),0) -> 0 | K34: No
G35: =IF(F35="USD",D35*E35*$F$11,IF(F35="Pesos",D35*E35,"<< Moneda ?")) -> << Moneda ? | J35: =IFERROR(G35*(1+I35)*(1+$M$28),0) -> 0 | K35: No
G36: =IF(F36="USD",D36*E36*$F$11,IF(F36="Pesos",D36*E36,"<< Moneda ?")) -> << Moneda ? | J36: =IFERROR(G36*(1+I36)*(1+$M$28),0) -> 0 | K36: No
G37: =IF(F37="USD",D37*E37*$F$11,IF(F37="Pesos",D37*E37,"<< Moneda ?")) -> << Moneda ? | J37: =IFERROR(G37*(1+I37)*(1+$M$28),0) -> 0 | K37: No
G38: =IF(F38="USD",D38*E38*$F$11,IF(F38="Pesos",D38*E38,"<< Moneda ?")) -> << Moneda ? | J38: =IFERROR(G38*(1+I38)*(1+$M$28),0) -> 0 | K38: No
G39: =IF(F39="USD",D39*E39*$F$11,IF(F39="Pesos",D39*E39,"<< Moneda ?")) -> << Moneda ? | J39: =IFERROR(G39*(1+I39)*(1+$M$28),0) -> 0 | K39: No
G40: =IF(F40="USD",D40*E40*$F$11,IF(F40="Pesos",D40*E40,"<< Moneda ?")) -> << Moneda ? | J40: =IFERROR(G40*(1+I40)*(1+$M$28),0) -> 0 | K40: No
H41: Utilidad promedio del rubro materiales | I41: =IFERROR(AVERAGEIF(I31:I40,">0"),0) -> 0 | J41: =SUM(J31:J40) -> 0
E42: SUBTOTAL | F42: =SUBTOTAL(109,PRESUPUESTO!$G$31:$G$40) -> 0 | H42: Utilidad con ajuste | I42: =I41*(1+$M$28) -> 0
B45: ITEM | C45: DESCRIPCION | D45: HORAS | E45: CATEGORIA | F45: COSTO MO | G45: % de utilidad | H45: Venta en [$] | I45: ES GLOBAL | J45: Costo hora
F46: =IFERROR(D46*(VLOOKUP(E46,LISTAS!$H$3:$I$8,2,0)),0) -> 0 | H46: =IFERROR(F46*(1+G46)*(1+$M$28),0) -> 0 | I46: No | J46: =IFERROR(VLOOKUP(E46,LISTAS!$H$3:$I$8,2,0),0) -> 0 | K46: EN REVISIONES HAY QUE CAMBIAR MANUALMENTE EL COSTO POR LA CANTIDAD.
F47: =IFERROR(D47*(VLOOKUP(E47,LISTAS!$H$3:$I$8,2,0)),0) -> 0 | H47: =IFERROR(F47*(1+G47)*(1+$M$28),0) -> 0 | I47: No | J47: =IFERROR(VLOOKUP(E47,LISTAS!$H$3:$I$8,2,0),0) -> 0
...
